<?xml version="1.0" encoding="UTF-8"?>
<!-- Generated by org.testng.reporters.JUnitReportReporter -->
<testsuite hostname="DESKTOP-LJ15L86" failures="0" tests="1" name="testngSessions.ExpectedException" time="0.010" errors="1" timestamp="2020-07-07T18:54:46 CDT" skipped="0">
  <testcase classname="testngSessions.ExpectedException" name="getNumberTest" time="0.010">
    <error message="
Method ExpectedException.getNumberTest()[pri:0, instance:testngSessions.ExpectedException@7f1302d6] should have thrown an exception of any of types [class java.lang.ArithmeticException, class java.lang.NullPointerException]" type="org.testng.TestException">
      <![CDATA[org.testng.TestException: 
Method ExpectedException.getNumberTest()[pri:0, instance:testngSessions.ExpectedException@7f1302d6] should have thrown an exception of any of types [class java.lang.ArithmeticException, class java.lang.NullPointerException]
at org.testng.internal.ExpectedExceptionsHolder.noException(ExpectedExceptionsHolder.java:82)
at org.testng.internal.TestInvoker.considerExceptions(TestInvoker.java:741)
at org.testng.internal.TestInvoker.invokeMethod(TestInvoker.java:629)
at org.testng.internal.TestInvoker.invokeTestMethod(TestInvoker.java:173)
at org.testng.internal.MethodRunner.runInSequence(MethodRunner.java:46)
at org.testng.internal.TestInvoker$MethodInvocationAgent.invoke(TestInvoker.java:816)
at org.testng.internal.TestInvoker.invokeTestMethods(TestInvoker.java:146)
at org.testng.internal.TestMethodWorker.invokeTestMethods(TestMethodWorker.java:146)
at org.testng.internal.TestMethodWorker.run(TestMethodWorker.java:128)
at java.base/java.util.ArrayList.forEach(ArrayList.java:1507)
at org.testng.TestRunner.privateRun(TestRunner.java:766)
at org.testng.TestRunner.run(TestRunner.java:587)
at org.testng.SuiteRunner.runTest(SuiteRunner.java:384)
at org.testng.SuiteRunner.runSequentially(SuiteRunner.java:378)
at org.testng.SuiteRunner.privateRun(SuiteRunner.java:337)
at org.testng.SuiteRunner.run(SuiteRunner.java:286)
at org.testng.SuiteRunnerWorker.runSuite(SuiteRunnerWorker.java:53)
at org.testng.SuiteRunnerWorker.run(SuiteRunnerWorker.java:96)
at org.testng.TestNG.runSuitesSequentially(TestNG.java:1187)
at org.testng.TestNG.runSuitesLocally(TestNG.java:1109)
at org.testng.TestNG.runSuites(TestNG.java:1039)
at org.testng.TestNG.run(TestNG.java:1007)
at org.testng.remote.AbstractRemoteTestNG.run(AbstractRemoteTestNG.java:115)
at org.testng.remote.RemoteTestNG.initAndRun(RemoteTestNG.java:251)
at org.testng.remote.RemoteTestNG.main(RemoteTestNG.java:77)
]]>
    </error>
  </testcase> <!-- getNumberTest -->
  <system-out/>
</testsuite> <!-- testngSessions.ExpectedException -->
